Traceback (most recent call last):
  File "/usr/lib/python3.7/urllib/request.py", line 1324, in do_open
    encode_chunked=req.has_header('Transfer-encoding'))
  File "/usr/lib/python3.7/http/client.py", line 1244, in request
    self._send_request(method, url, body, headers, encode_chunked)
  File "/usr/lib/python3.7/http/client.py", line 1290, in _send_request
    self.endheaders(body, encode_chunked=encode_chunked)
  File "/usr/lib/python3.7/http/client.py", line 1239, in endheaders
    self._send_output(message_body, encode_chunked=encode_chunked)
  File "/usr/lib/python3.7/http/client.py", line 1026, in _send_output
    self.send(msg)
  File "/usr/lib/python3.7/http/client.py", line 966, in send
    self.connect()
  File "/usr/lib/python3.7/http/client.py", line 1399, in connect
    super().connect()
  File "/usr/lib/python3.7/http/client.py", line 938, in connect
    (self.host,self.port), self.timeout, self.source_address)
  File "/usr/lib/python3.7/socket.py", line 707, in create_connection
    for res in getaddrinfo(host, port, 0, SOCK_STREAM):
  File "/usr/lib/python3.7/socket.py", line 748, in getaddrinfo
    for res in _socket.getaddrinfo(host, port, family, type, proto, flags):
socket.gaierror: [Errno -3] Temporary failure in name resolution

During handling of the above exception, another exception occurred:

Traceback (most recent call last):
  File "/home/pi/.local/lib/python3.7/site-packages/youtubesearchpython/handlers/requesthandler.py", line 36, in _makeRequest
    self.response = urlopen(request).read().decode('utf_8')
  File "/usr/lib/python3.7/urllib/request.py", line 222, in urlopen
    return opener.open(url, data, timeout)
  File "/usr/lib/python3.7/urllib/request.py", line 525, in open
    response = self._open(req, data)
  File "/usr/lib/python3.7/urllib/request.py", line 543, in _open
    '_open', req)
  File "/usr/lib/python3.7/urllib/request.py", line 503, in _call_chain
    result = func(*args)
  File "/usr/lib/python3.7/urllib/request.py", line 1367, in https_open
    context=self._context, check_hostname=self._check_hostname)
  File "/usr/lib/python3.7/urllib/request.py", line 1326, in do_open
    raise URLError(err)
urllib.error.URLError: <urlopen error [Errno -3] Temporary failure in name resolution>

During handling of the above exception, another exception occurred:

Traceback (most recent call last):
  File "./main.py", line 171, in <module>
    main()
  File "./main.py", line 63, in main
    sentence, result = sklearn_sims.compare_command(sentence, classes)
  File "/home/pi/Documents/DOORS/tools/sklearn_sims.py", line 132, in compare_command
    msg, function = mods[bMod].command_handler(spoken)
  File "/home/pi/Documents/DOORS/modules/youtube_music.py", line 108, in command_handler
    function = download_song(result[0])
  File "/home/pi/Documents/DOORS/modules/youtube_music.py", line 27, in download_song
    videosSearch = VideosSearch(songName, limit = 2) #searching information about song
  File "/home/pi/.local/lib/python3.7/site-packages/youtubesearchpython/search.py", line 142, in __init__
    super().__init__(query, limit, language, region, SearchMode.videos)
  File "/home/pi/.local/lib/python3.7/site-packages/youtubesearchpython/internal/search.py", line 20, in __init__
    self._makeRequest()
  File "/home/pi/.local/lib/python3.7/site-packages/youtubesearchpython/handlers/requesthandler.py", line 38, in _makeRequest
    raise Exception('ERROR: Could not make request.')
Exception: ERROR: Could not make request.